Traceback (most recent call last):
  File "/local/a/jgammell/dlsca_bag_of_tricks/src/main.py", line 111, in run_wandb_trial_
    trainer.train_model(settings['total_epochs'], results_save_dir=results_save_dir, model_save_dir=model_save_dir)
  File "/local/a/jgammell/dlsca_bag_of_tricks/src/train/weird_gan.py", line 404, in train_model
    self.reset(epochs)
  File "/local/a/jgammell/dlsca_bag_of_tricks/src/train/weird_gan.py", line 91, in reset
    self.train_dataset = datasets.construct_dataset(self.dataset_name, train=True, **self.dataset_kwargs)
  File "/local/a/jgammell/dlsca_bag_of_tricks/src/datasets/__init__.py", line 22, in construct_dataset
    dataset = dataset_class(**dataset_kwargs)
  File "/local/a/jgammell/dlsca_bag_of_tricks/src/datasets/google_tinyaes.py", line 84, in __init__
    super().__init__(train=train, **kwargs)
  File "/local/a/jgammell/dlsca_bag_of_tricks/src/datasets/common.py", line 54, in __init__
    eg_data, _ = self.__getitem__(0)
  File "/local/a/jgammell/dlsca_bag_of_tricks/src/datasets/common.py", line 71, in __getitem__
    data, target = self.load_idx(idx)
  File "/local/a/jgammell/dlsca_bag_of_tricks/src/datasets/google_tinyaes.py", line 94, in load_idx
    return trace, target
NameError: name 'trace' is not defined